<?xml version="1.0"?>
<!--
  Simple Mobile Robot with LiDAR
  4-wheel drive robot with top-mounted LiDAR sensor
-->
<robot name="mobile_robot">

  <!-- Base Platform -->
  <link name="base_link">
    <visual>
      <geometry>
        <box size="0.40 0.30 0.12"/>
      </geometry>
      <material name="base_material">
        <color rgba="0.2 0.2 0.2 1.0"/>
      </material>
    </visual>
    <collision>
      <geometry>
        <box size="0.40 0.30 0.12"/>
      </geometry>
    </collision>
    <inertial>
      <mass value="8.0"/>
      <origin xyz="0 0 0" rpy="0 0 0"/>
      <inertia ixx="0.0696" ixy="0.0" ixz="0.0" iyy="0.1163" iyz="0.0" izz="0.1667"/>
    </inertial>
  </link>

  <!-- Front Left Wheel -->
  <link name="front_left_wheel">
    <visual>
      <origin xyz="0 0 0" rpy="1.57079632679 0 0"/>
      <geometry>
        <cylinder radius="0.08" length="0.05"/>
      </geometry>
      <material name="wheel_material">
        <color rgba="0.1 0.1 0.1 1.0"/>
      </material>
    </visual>
    <collision>
      <origin xyz="0 0 0" rpy="1.57079632679 0 0"/>
      <geometry>
        <cylinder radius="0.08" length="0.05"/>
      </geometry>
    </collision>
    <inertial>
      <mass value="0.6"/>
      <origin xyz="0 0 0" rpy="0 0 0"/>
      <inertia ixx="0.001085" ixy="0.0" ixz="0.0" iyy="0.001085" iyz="0.0" izz="0.001920"/>
    </inertial>
  </link>

  <joint name="front_left_wheel_joint" type="continuous">
    <parent link="base_link"/>
    <child link="front_left_wheel"/>
    <origin xyz="0.12 0.175 -0.02" rpy="0 0 0"/>
    <axis xyz="0 1 0"/>
    <dynamics damping="0.1" friction="0.1"/>
  </joint>

  <!-- Front Right Wheel -->
  <link name="front_right_wheel">
    <visual>
      <origin xyz="0 0 0" rpy="1.57079632679 0 0"/>
      <geometry>
        <cylinder radius="0.08" length="0.05"/>
      </geometry>
      <material name="wheel_material">
        <color rgba="0.1 0.1 0.1 1.0"/>
      </material>
    </visual>
    <collision>
      <origin xyz="0 0 0" rpy="1.57079632679 0 0"/>
      <geometry>
        <cylinder radius="0.08" length="0.05"/>
      </geometry>
    </collision>
    <inertial>
      <mass value="0.6"/>
      <origin xyz="0 0 0" rpy="0 0 0"/>
      <inertia ixx="0.001085" ixy="0.0" ixz="0.0" iyy="0.001085" iyz="0.0" izz="0.001920"/>
    </inertial>
  </link>

  <joint name="front_right_wheel_joint" type="continuous">
    <parent link="base_link"/>
    <child link="front_right_wheel"/>
    <origin xyz="0.12 -0.175 -0.02" rpy="0 0 0"/>
    <axis xyz="0 1 0"/>
    <dynamics damping="0.1" friction="0.1"/>
  </joint>

  <!-- Rear Left Wheel -->
  <link name="rear_left_wheel">
    <visual>
      <origin xyz="0 0 0" rpy="1.57079632679 0 0"/>
      <geometry>
        <cylinder radius="0.08" length="0.05"/>
      </geometry>
      <material name="wheel_material">
        <color rgba="0.1 0.1 0.1 1.0"/>
      </material>
    </visual>
    <collision>
      <origin xyz="0 0 0" rpy="1.57079632679 0 0"/>
      <geometry>
        <cylinder radius="0.08" length="0.05"/>
      </geometry>
    </collision>
    <inertial>
      <mass value="0.6"/>
      <origin xyz="0 0 0" rpy="0 0 0"/>
      <inertia ixx="0.001085" ixy="0.0" ixz="0.0" iyy="0.001085" iyz="0.0" izz="0.001920"/>
    </inertial>
  </link>

  <joint name="rear_left_wheel_joint" type="continuous">
    <parent link="base_link"/>
    <child link="rear_left_wheel"/>
    <origin xyz="-0.12 0.175 -0.02" rpy="0 0 0"/>
    <axis xyz="0 1 0"/>
    <dynamics damping="0.1" friction="0.1"/>
  </joint>

  <!-- Rear Right Wheel -->
  <link name="rear_right_wheel">
    <visual>
      <origin xyz="0 0 0" rpy="1.57079632679 0 0"/>
      <geometry>
        <cylinder radius="0.08" length="0.05"/>
      </geometry>
      <material name="wheel_material">
        <color rgba="0.1 0.1 0.1 1.0"/>
      </material>
    </visual>
    <collision>
      <origin xyz="0 0 0" rpy="1.57079632679 0 0"/>
      <geometry>
        <cylinder radius="0.08" length="0.05"/>
      </geometry>
    </collision>
    <inertial>
      <mass value="0.6"/>
      <origin xyz="0 0 0" rpy="0 0 0"/>
      <inertia ixx="0.001085" ixy="0.0" ixz="0.0" iyy="0.001085" iyz="0.0" izz="0.001920"/>
    </inertial>
  </link>

  <joint name="rear_right_wheel_joint" type="continuous">
    <parent link="base_link"/>
    <child link="rear_right_wheel"/>
    <origin xyz="-0.12 -0.175 -0.02" rpy="0 0 0"/>
    <axis xyz="0 1 0"/>
    <dynamics damping="0.1" friction="0.1"/>
  </joint>

  <!-- LiDAR Sensor -->
  <link name="lidar">
    <visual>
      <geometry>
        <cylinder radius="0.04" length="0.05"/>
      </geometry>
      <material name="lidar_material">
        <color rgba="0.1 0.1 0.1 1.0"/>
      </material>
    </visual>
    <collision>
      <geometry>
        <cylinder radius="0.04" length="0.05"/>
      </geometry>
    </collision>
    <inertial>
      <mass value="0.2"/>
      <origin xyz="0 0 0" rpy="0 0 0"/>
      <inertia ixx="0.00012167" ixy="0.0" ixz="0.0" iyy="0.00012167" iyz="0.0" izz="0.00016000"/>
    </inertial>
  </link>

  <joint name="lidar_joint" type="fixed">
    <parent link="base_link"/>
    <child link="lidar"/>
    <origin xyz="0 0 0.085" rpy="0 0 0"/>
  </joint>

</robot>
