<?xml version="1.0" ?>
<robot name="simple_arm">
  <material name="gray">
    <color rgba="0.7 0.7 0.7 1.0"/>
  </material>
  <material name="blue">
    <color rgba="0.2 0.4 0.8 1.0"/>
  </material>
  <material name="orange">
    <color rgba="1.0 0.5 0.0 1.0"/>
  </material>
  <link name="base_link">
    <visual>
      <geometry>
        <cylinder radius="0.1" length="0.05"/>
      </geometry>
      <material name="gray"/>
    </visual>
    <collision>
      <geometry>
        <cylinder radius="0.1" length="0.05"/>
      </geometry>
    </collision>
    <inertial>
      <mass value="1.0"/>
      <inertia ixx="0.002708333333333334" ixy="0.0" ixz="0.0" iyy="0.002708333333333334" iyz="0.0" izz="0.005000000000000001"/>
    </inertial>
  </link>
  <link name="link1">
    <visual>
      <origin xyz="0 0 0.15" rpy="0.0 0.0 0.0"/>
      <geometry>
        <box size="0.05 0.05 0.3"/>
      </geometry>
      <material name="blue"/>
    </visual>
    <collision>
      <origin xyz="0 0 0.15" rpy="0.0 0.0 0.0"/>
      <geometry>
        <box size="0.05 0.05 0.3"/>
      </geometry>
    </collision>
    <inertial>
      <origin xyz="0 0 0.15" rpy="0.0 0.0 0.0"/>
      <mass value="0.5"/>
      <inertia ixx="0.0038541666666666663" ixy="0.0" ixz="0.0" iyy="0.0038541666666666663" iyz="0.0" izz="0.00020833333333333337"/>
    </inertial>
  </link>
  <link name="link2">
    <visual>
      <origin xyz="0 0 0.125" rpy="0.0 0.0 0.0"/>
      <geometry>
        <box size="0.05 0.05 0.25"/>
      </geometry>
      <material name="orange"/>
    </visual>
    <collision>
      <origin xyz="0 0 0.125" rpy="0.0 0.0 0.0"/>
      <geometry>
        <box size="0.05 0.05 0.25"/>
      </geometry>
    </collision>
    <inertial>
      <origin xyz="0 0 0.125" rpy="0.0 0.0 0.0"/>
      <mass value="0.3"/>
      <inertia ixx="0.001625" ixy="0.0" ixz="0.0" iyy="0.001625" iyz="0.0" izz="0.000125"/>
    </inertial>
  </link>
  <joint name="joint1" type="revolute">
    <origin xyz="0 0 0.025" rpy="0.0 0.0 0.0"/>
    <parent link="base_link"/>
    <child link="link1"/>
    <axis xyz="0 0 1"/>
    <limit lower="-3.141592653589793" upper="3.141592653589793" effort="10.0" velocity="2.0"/>
  </joint>
  <joint name="joint2" type="revolute">
    <origin xyz="0 0 0.3" rpy="0.0 0.0 0.0"/>
    <parent link="link1"/>
    <child link="link2"/>
    <axis xyz="0 1 0"/>
    <limit lower="-1.5707963267948966" upper="1.5707963267948966" effort="5.0" velocity="2.0"/>
  </joint>
</robot>
